{
  "nbformat": 4,
  "nbformat_minor": 0,
  "metadata": {
    "colab": {
      "name": "Timbrenet_Execution.ipynb",
      "provenance": [],
      "mount_file_id": "1lfOx4OwnLFmgVf7v83v5SMMuPAdWenfm",
      "authorship_tag": "ABX9TyNxRcZrFE2qFRJyMb7PmS31",
      "include_colab_link": true
    },
    "kernelspec": {
      "name": "python3",
      "display_name": "Python 3"
    },
    "accelerator": "GPU"
  },
  "cells": [
    {
      "cell_type": "markdown",
      "metadata": {
        "id": "view-in-github",
        "colab_type": "text"
      },
      "source": [
        "<a href=\"https://colab.research.google.com/github/revs1/Simple_ML_notebooks-revs96/blob/master/Timbrenet_Execution.ipynb\" target=\"_parent\"><img src=\"https://colab.research.google.com/assets/colab-badge.svg\" alt=\"Open In Colab\"/></a>"
      ]
    },
    {
      "cell_type": "code",
      "metadata": {
        "id": "QFEZ8AdmaDLS",
        "colab_type": "code",
        "outputId": "16cc803e-fbe2-4780-d299-c92757574910",
        "colab": {
          "base_uri": "https://localhost:8080/",
          "height": 34
        }
      },
      "source": [
        "%cd /content/drive/My Drive/Colab Notebooks/Github Projects\n"
      ],
      "execution_count": 0,
      "outputs": [
        {
          "output_type": "stream",
          "text": [
            "/content/drive/My Drive/Colab Notebooks/Github Projects\n"
          ],
          "name": "stdout"
        }
      ]
    },
    {
      "cell_type": "code",
      "metadata": {
        "id": "2I9OFH-IaaUw",
        "colab_type": "code",
        "outputId": "6791a4aa-2bc2-4507-a9de-384e18b0e595",
        "colab": {
          "base_uri": "https://localhost:8080/",
          "height": 153
        }
      },
      "source": [
        "! git clone https://github.com/CreativAI-UC/TimbreNet\n"
      ],
      "execution_count": 0,
      "outputs": [
        {
          "output_type": "stream",
          "text": [
            "Cloning into 'TimbreNet'...\n",
            "remote: Enumerating objects: 3, done.\u001b[K\n",
            "remote: Counting objects: 100% (3/3), done.\u001b[K\n",
            "remote: Compressing objects: 100% (3/3), done.\u001b[K\n",
            "remote: Total 1126 (delta 0), reused 2 (delta 0), pack-reused 1123\u001b[K\n",
            "Receiving objects: 100% (1126/1126), 280.89 MiB | 17.42 MiB/s, done.\n",
            "Resolving deltas: 100% (62/62), done.\n",
            "Checking out files: 100% (497/497), done.\n"
          ],
          "name": "stdout"
        }
      ]
    },
    {
      "cell_type": "code",
      "metadata": {
        "id": "cZHgJCczat-B",
        "colab_type": "code",
        "outputId": "71ec7ec2-1ddf-4a9f-c96f-662b4e68ee2b",
        "colab": {
          "base_uri": "https://localhost:8080/",
          "height": 34
        }
      },
      "source": [
        "%cd /content/drive/My Drive/Colab Notebooks/Github Projects/TimbreNet\n"
      ],
      "execution_count": 0,
      "outputs": [
        {
          "output_type": "stream",
          "text": [
            "/content/drive/My Drive/Colab Notebooks/Github Projects/TimbreNet\n"
          ],
          "name": "stdout"
        }
      ]
    },
    {
      "cell_type": "code",
      "metadata": {
        "id": "znszQ0T8bQOH",
        "colab_type": "code",
        "outputId": "a3942a9c-4571-4513-d2b0-cbdc7f64a8d6",
        "colab": {
          "base_uri": "https://localhost:8080/",
          "height": 1000
        }
      },
      "source": [
        "!python timbrenet_generate_chord.py"
      ],
      "execution_count": 0,
      "outputs": [
        {
          "output_type": "stream",
          "text": [
            "2020-05-15 08:23:39.164196: I tensorflow/stream_executor/platform/default/dso_loader.cc:44] Successfully opened dynamic library libcudart.so.10.1\n",
            "2020-05-15 08:23:41.033111: I tensorflow/stream_executor/platform/default/dso_loader.cc:44] Successfully opened dynamic library libcuda.so.1\n",
            "2020-05-15 08:23:41.081991: I tensorflow/stream_executor/cuda/cuda_gpu_executor.cc:981] successful NUMA node read from SysFS had negative value (-1), but there must be at least one NUMA node, so returning NUMA node zero\n",
            "2020-05-15 08:23:41.082659: I tensorflow/core/common_runtime/gpu/gpu_device.cc:1561] Found device 0 with properties: \n",
            "pciBusID: 0000:00:04.0 name: Tesla P4 computeCapability: 6.1\n",
            "coreClock: 1.1135GHz coreCount: 20 deviceMemorySize: 7.43GiB deviceMemoryBandwidth: 178.99GiB/s\n",
            "2020-05-15 08:23:41.082711: I tensorflow/stream_executor/platform/default/dso_loader.cc:44] Successfully opened dynamic library libcudart.so.10.1\n",
            "2020-05-15 08:23:41.349165: I tensorflow/stream_executor/platform/default/dso_loader.cc:44] Successfully opened dynamic library libcublas.so.10\n",
            "2020-05-15 08:23:41.475366: I tensorflow/stream_executor/platform/default/dso_loader.cc:44] Successfully opened dynamic library libcufft.so.10\n",
            "2020-05-15 08:23:41.505072: I tensorflow/stream_executor/platform/default/dso_loader.cc:44] Successfully opened dynamic library libcurand.so.10\n",
            "2020-05-15 08:23:41.767724: I tensorflow/stream_executor/platform/default/dso_loader.cc:44] Successfully opened dynamic library libcusolver.so.10\n",
            "2020-05-15 08:23:41.813276: I tensorflow/stream_executor/platform/default/dso_loader.cc:44] Successfully opened dynamic library libcusparse.so.10\n",
            "2020-05-15 08:23:42.335824: I tensorflow/stream_executor/platform/default/dso_loader.cc:44] Successfully opened dynamic library libcudnn.so.7\n",
            "2020-05-15 08:23:42.336006: I tensorflow/stream_executor/cuda/cuda_gpu_executor.cc:981] successful NUMA node read from SysFS had negative value (-1), but there must be at least one NUMA node, so returning NUMA node zero\n",
            "2020-05-15 08:23:42.336680: I tensorflow/stream_executor/cuda/cuda_gpu_executor.cc:981] successful NUMA node read from SysFS had negative value (-1), but there must be at least one NUMA node, so returning NUMA node zero\n",
            "2020-05-15 08:23:42.337288: I tensorflow/core/common_runtime/gpu/gpu_device.cc:1703] Adding visible gpu devices: 0\n",
            "2020-05-15 08:23:42.337652: I tensorflow/core/platform/cpu_feature_guard.cc:143] Your CPU supports instructions that this TensorFlow binary was not compiled to use: AVX512F\n",
            "2020-05-15 08:23:42.363414: I tensorflow/core/platform/profile_utils/cpu_utils.cc:102] CPU Frequency: 2000160000 Hz\n",
            "2020-05-15 08:23:42.363638: I tensorflow/compiler/xla/service/service.cc:168] XLA service 0x2894bc0 initialized for platform Host (this does not guarantee that XLA will be used). Devices:\n",
            "2020-05-15 08:23:42.363676: I tensorflow/compiler/xla/service/service.cc:176]   StreamExecutor device (0): Host, Default Version\n",
            "2020-05-15 08:23:42.519674: I tensorflow/stream_executor/cuda/cuda_gpu_executor.cc:981] successful NUMA node read from SysFS had negative value (-1), but there must be at least one NUMA node, so returning NUMA node zero\n",
            "2020-05-15 08:23:42.520208: I tensorflow/compiler/xla/service/service.cc:168] XLA service 0x2894d80 initialized for platform CUDA (this does not guarantee that XLA will be used). Devices:\n",
            "2020-05-15 08:23:42.520238: I tensorflow/compiler/xla/service/service.cc:176]   StreamExecutor device (0): Tesla P4, Compute Capability 6.1\n",
            "2020-05-15 08:23:42.521395: I tensorflow/stream_executor/cuda/cuda_gpu_executor.cc:981] successful NUMA node read from SysFS had negative value (-1), but there must be at least one NUMA node, so returning NUMA node zero\n",
            "2020-05-15 08:23:42.521791: I tensorflow/core/common_runtime/gpu/gpu_device.cc:1561] Found device 0 with properties: \n",
            "pciBusID: 0000:00:04.0 name: Tesla P4 computeCapability: 6.1\n",
            "coreClock: 1.1135GHz coreCount: 20 deviceMemorySize: 7.43GiB deviceMemoryBandwidth: 178.99GiB/s\n",
            "2020-05-15 08:23:42.521837: I tensorflow/stream_executor/platform/default/dso_loader.cc:44] Successfully opened dynamic library libcudart.so.10.1\n",
            "2020-05-15 08:23:42.521891: I tensorflow/stream_executor/platform/default/dso_loader.cc:44] Successfully opened dynamic library libcublas.so.10\n",
            "2020-05-15 08:23:42.521915: I tensorflow/stream_executor/platform/default/dso_loader.cc:44] Successfully opened dynamic library libcufft.so.10\n",
            "2020-05-15 08:23:42.521937: I tensorflow/stream_executor/platform/default/dso_loader.cc:44] Successfully opened dynamic library libcurand.so.10\n",
            "2020-05-15 08:23:42.521957: I tensorflow/stream_executor/platform/default/dso_loader.cc:44] Successfully opened dynamic library libcusolver.so.10\n",
            "2020-05-15 08:23:42.521976: I tensorflow/stream_executor/platform/default/dso_loader.cc:44] Successfully opened dynamic library libcusparse.so.10\n",
            "2020-05-15 08:23:42.521996: I tensorflow/stream_executor/platform/default/dso_loader.cc:44] Successfully opened dynamic library libcudnn.so.7\n",
            "2020-05-15 08:23:42.522065: I tensorflow/stream_executor/cuda/cuda_gpu_executor.cc:981] successful NUMA node read from SysFS had negative value (-1), but there must be at least one NUMA node, so returning NUMA node zero\n",
            "2020-05-15 08:23:42.522486: I tensorflow/stream_executor/cuda/cuda_gpu_executor.cc:981] successful NUMA node read from SysFS had negative value (-1), but there must be at least one NUMA node, so returning NUMA node zero\n",
            "2020-05-15 08:23:42.522841: I tensorflow/core/common_runtime/gpu/gpu_device.cc:1703] Adding visible gpu devices: 0\n",
            "2020-05-15 08:23:42.527622: I tensorflow/stream_executor/platform/default/dso_loader.cc:44] Successfully opened dynamic library libcudart.so.10.1\n",
            "2020-05-15 08:23:48.917142: I tensorflow/core/common_runtime/gpu/gpu_device.cc:1102] Device interconnect StreamExecutor with strength 1 edge matrix:\n",
            "2020-05-15 08:23:48.917201: I tensorflow/core/common_runtime/gpu/gpu_device.cc:1108]      0 \n",
            "2020-05-15 08:23:48.917217: I tensorflow/core/common_runtime/gpu/gpu_device.cc:1121] 0:   N \n",
            "2020-05-15 08:23:48.921993: I tensorflow/stream_executor/cuda/cuda_gpu_executor.cc:981] successful NUMA node read from SysFS had negative value (-1), but there must be at least one NUMA node, so returning NUMA node zero\n",
            "2020-05-15 08:23:48.922506: I tensorflow/stream_executor/cuda/cuda_gpu_executor.cc:981] successful NUMA node read from SysFS had negative value (-1), but there must be at least one NUMA node, so returning NUMA node zero\n",
            "2020-05-15 08:23:48.922933: W tensorflow/core/common_runtime/gpu/gpu_bfc_allocator.cc:39] Overriding allow_growth setting because the TF_FORCE_GPU_ALLOW_GROWTH environment variable is set. Original config value was 0.\n",
            "2020-05-15 08:23:48.922994: I tensorflow/core/common_runtime/gpu/gpu_device.cc:1247] Created TensorFlow device (/job:localhost/replica:0/task:0/device:GPU:0 with 6966 MB memory) -> physical GPU (device: 0, name: Tesla P4, pci bus id: 0000:00:04.0, compute capability: 6.1)\n",
            "\n",
            "\n",
            "Loading Trained Model...\n",
            "WARNING:tensorflow:Inconsistent references when loading the checkpoint into this object graph. Either the Trackable object references in the Python program have changed in an incompatible way, or the checkpoint was generated in an incompatible program.\n",
            "\n",
            "Two checkpoint references resolved to different objects (<tensorflow.python.keras.layers.convolutional.Conv2D object at 0x7fad485ebf98> and <tensorflow.python.keras.layers.convolutional.Conv2D object at 0x7fad31ad0a90>).\n",
            "WARNING:tensorflow:Inconsistent references when loading the checkpoint into this object graph. Either the Trackable object references in the Python program have changed in an incompatible way, or the checkpoint was generated in an incompatible program.\n",
            "\n",
            "Two checkpoint references resolved to different objects (<tensorflow.python.keras.layers.convolutional.Conv2D object at 0x7fad31ad0a90> and <tensorflow.python.keras.layers.convolutional.Conv2D object at 0x7fad31ad0f28>).\n",
            "WARNING:tensorflow:Inconsistent references when loading the checkpoint into this object graph. Either the Trackable object references in the Python program have changed in an incompatible way, or the checkpoint was generated in an incompatible program.\n",
            "\n",
            "Two checkpoint references resolved to different objects (<tensorflow.python.keras.layers.convolutional.Conv2D object at 0x7fad31ad0f28> and <tensorflow.python.keras.layers.pooling.AveragePooling2D object at 0x7fad31b042e8>).\n",
            "WARNING:tensorflow:Inconsistent references when loading the checkpoint into this object graph. Either the Trackable object references in the Python program have changed in an incompatible way, or the checkpoint was generated in an incompatible program.\n",
            "\n",
            "Two checkpoint references resolved to different objects (<tensorflow.python.keras.layers.convolutional.Conv2D object at 0x7fad31b045c0> and <tensorflow.python.keras.layers.convolutional.Conv2D object at 0x7fad31b04a58>).\n",
            "WARNING:tensorflow:Inconsistent references when loading the checkpoint into this object graph. Either the Trackable object references in the Python program have changed in an incompatible way, or the checkpoint was generated in an incompatible program.\n",
            "\n",
            "Two checkpoint references resolved to different objects (<tensorflow.python.keras.layers.convolutional.Conv2D object at 0x7fad31b04a58> and <tensorflow.python.keras.layers.pooling.AveragePooling2D object at 0x7fad31b04dd8>).\n",
            "WARNING:tensorflow:Inconsistent references when loading the checkpoint into this object graph. Either the Trackable object references in the Python program have changed in an incompatible way, or the checkpoint was generated in an incompatible program.\n",
            "\n",
            "Two checkpoint references resolved to different objects (<tensorflow.python.keras.layers.convolutional.Conv2D object at 0x7fad31b100f0> and <tensorflow.python.keras.layers.convolutional.Conv2D object at 0x7fad31b10588>).\n",
            "WARNING:tensorflow:Inconsistent references when loading the checkpoint into this object graph. Either the Trackable object references in the Python program have changed in an incompatible way, or the checkpoint was generated in an incompatible program.\n",
            "\n",
            "Two checkpoint references resolved to different objects (<tensorflow.python.keras.layers.convolutional.Conv2D object at 0x7fad31b10588> and <tensorflow.python.keras.layers.pooling.AveragePooling2D object at 0x7fad31b10908>).\n",
            "WARNING:tensorflow:Inconsistent references when loading the checkpoint into this object graph. Either the Trackable object references in the Python program have changed in an incompatible way, or the checkpoint was generated in an incompatible program.\n",
            "\n",
            "Two checkpoint references resolved to different objects (<tensorflow.python.keras.layers.convolutional.Conv2D object at 0x7fad31b10be0> and <tensorflow.python.keras.layers.convolutional.Conv2D object at 0x7fad31b190b8>).\n",
            "WARNING:tensorflow:Inconsistent references when loading the checkpoint into this object graph. Either the Trackable object references in the Python program have changed in an incompatible way, or the checkpoint was generated in an incompatible program.\n",
            "\n",
            "Two checkpoint references resolved to different objects (<tensorflow.python.keras.layers.convolutional.Conv2D object at 0x7fad31b190b8> and <tensorflow.python.keras.layers.pooling.AveragePooling2D object at 0x7fad31b19438>).\n",
            "WARNING:tensorflow:Inconsistent references when loading the checkpoint into this object graph. Either the Trackable object references in the Python program have changed in an incompatible way, or the checkpoint was generated in an incompatible program.\n",
            "\n",
            "Two checkpoint references resolved to different objects (<tensorflow.python.keras.layers.convolutional.Conv2D object at 0x7fad31b19710> and <tensorflow.python.keras.layers.convolutional.Conv2D object at 0x7fad31b19ba8>).\n",
            "WARNING:tensorflow:Inconsistent references when loading the checkpoint into this object graph. Either the Trackable object references in the Python program have changed in an incompatible way, or the checkpoint was generated in an incompatible program.\n",
            "\n",
            "Two checkpoint references resolved to different objects (<tensorflow.python.keras.layers.convolutional.Conv2D object at 0x7fad31b19ba8> and <tensorflow.python.keras.layers.pooling.AveragePooling2D object at 0x7fad31b19f28>).\n",
            "WARNING:tensorflow:Inconsistent references when loading the checkpoint into this object graph. Either the Trackable object references in the Python program have changed in an incompatible way, or the checkpoint was generated in an incompatible program.\n",
            "\n",
            "Two checkpoint references resolved to different objects (<tensorflow.python.keras.layers.convolutional.Conv2D object at 0x7fad31a65240> and <tensorflow.python.keras.layers.convolutional.Conv2D object at 0x7fad31a656d8>).\n",
            "WARNING:tensorflow:Inconsistent references when loading the checkpoint into this object graph. Either the Trackable object references in the Python program have changed in an incompatible way, or the checkpoint was generated in an incompatible program.\n",
            "\n",
            "Two checkpoint references resolved to different objects (<tensorflow.python.keras.layers.convolutional.Conv2D object at 0x7fad31a656d8> and <tensorflow.python.keras.layers.pooling.AveragePooling2D object at 0x7fad31a65a58>).\n",
            "WARNING:tensorflow:Inconsistent references when loading the checkpoint into this object graph. Either the Trackable object references in the Python program have changed in an incompatible way, or the checkpoint was generated in an incompatible program.\n",
            "\n",
            "Two checkpoint references resolved to different objects (<tensorflow.python.keras.layers.convolutional.Conv2D object at 0x7fad31a65d30> and <tensorflow.python.keras.layers.convolutional.Conv2D object at 0x7fad31a6e208>).\n",
            "WARNING:tensorflow:Inconsistent references when loading the checkpoint into this object graph. Either the Trackable object references in the Python program have changed in an incompatible way, or the checkpoint was generated in an incompatible program.\n",
            "\n",
            "Two checkpoint references resolved to different objects (<tensorflow.python.keras.layers.convolutional.Conv2D object at 0x7fad31a6e208> and <tensorflow.python.keras.layers.pooling.AveragePooling2D object at 0x7fad31a6e588>).\n",
            "WARNING:tensorflow:Inconsistent references when loading the checkpoint into this object graph. Either the Trackable object references in the Python program have changed in an incompatible way, or the checkpoint was generated in an incompatible program.\n",
            "\n",
            "Two checkpoint references resolved to different objects (<tensorflow.python.keras.layers.core.Dense object at 0x7facd605f6a0> and <tensorflow.python.keras.layers.core.Reshape object at 0x7facd606b8d0>).\n",
            "WARNING:tensorflow:Inconsistent references when loading the checkpoint into this object graph. Either the Trackable object references in the Python program have changed in an incompatible way, or the checkpoint was generated in an incompatible program.\n",
            "\n",
            "Two checkpoint references resolved to different objects (<tensorflow.python.keras.layers.convolutional.Conv2DTranspose object at 0x7facd606beb8> and <tensorflow.python.keras.layers.normalization.LayerNormalization object at 0x7fad31aee240>).\n",
            "WARNING:tensorflow:Inconsistent references when loading the checkpoint into this object graph. Either the Trackable object references in the Python program have changed in an incompatible way, or the checkpoint was generated in an incompatible program.\n",
            "\n",
            "Two checkpoint references resolved to different objects (<tensorflow.python.keras.layers.normalization.LayerNormalization object at 0x7fad31aee240> and <tensorflow.python.keras.layers.convolutional.Conv2DTranspose object at 0x7fad31aee550>).\n",
            "WARNING:tensorflow:Inconsistent references when loading the checkpoint into this object graph. Either the Trackable object references in the Python program have changed in an incompatible way, or the checkpoint was generated in an incompatible program.\n",
            "\n",
            "Two checkpoint references resolved to different objects (<tensorflow.python.keras.layers.convolutional.Conv2DTranspose object at 0x7fad31aee550> and <tensorflow.python.keras.layers.normalization.LayerNormalization object at 0x7fad31aee898>).\n",
            "WARNING:tensorflow:Inconsistent references when loading the checkpoint into this object graph. Either the Trackable object references in the Python program have changed in an incompatible way, or the checkpoint was generated in an incompatible program.\n",
            "\n",
            "Two checkpoint references resolved to different objects (<tensorflow.python.keras.layers.normalization.LayerNormalization object at 0x7fad31aee898> and <tensorflow.python.keras.layers.convolutional.UpSampling2D object at 0x7fad31aeea20>).\n",
            "WARNING:tensorflow:Inconsistent references when loading the checkpoint into this object graph. Either the Trackable object references in the Python program have changed in an incompatible way, or the checkpoint was generated in an incompatible program.\n",
            "\n",
            "Two checkpoint references resolved to different objects (<tensorflow.python.keras.layers.convolutional.Conv2DTranspose object at 0x7fad31aeecf8> and <tensorflow.python.keras.layers.normalization.LayerNormalization object at 0x7facd6077080>).\n",
            "WARNING:tensorflow:Inconsistent references when loading the checkpoint into this object graph. Either the Trackable object references in the Python program have changed in an incompatible way, or the checkpoint was generated in an incompatible program.\n",
            "\n",
            "Two checkpoint references resolved to different objects (<tensorflow.python.keras.layers.normalization.LayerNormalization object at 0x7facd6077080> and <tensorflow.python.keras.layers.convolutional.Conv2DTranspose object at 0x7facd6077390>).\n",
            "WARNING:tensorflow:Inconsistent references when loading the checkpoint into this object graph. Either the Trackable object references in the Python program have changed in an incompatible way, or the checkpoint was generated in an incompatible program.\n",
            "\n",
            "Two checkpoint references resolved to different objects (<tensorflow.python.keras.layers.convolutional.Conv2DTranspose object at 0x7facd6077390> and <tensorflow.python.keras.layers.normalization.LayerNormalization object at 0x7facd60776d8>).\n",
            "WARNING:tensorflow:Inconsistent references when loading the checkpoint into this object graph. Either the Trackable object references in the Python program have changed in an incompatible way, or the checkpoint was generated in an incompatible program.\n",
            "\n",
            "Two checkpoint references resolved to different objects (<tensorflow.python.keras.layers.normalization.LayerNormalization object at 0x7facd60776d8> and <tensorflow.python.keras.layers.convolutional.UpSampling2D object at 0x7facd6077860>).\n",
            "WARNING:tensorflow:Inconsistent references when loading the checkpoint into this object graph. Either the Trackable object references in the Python program have changed in an incompatible way, or the checkpoint was generated in an incompatible program.\n",
            "\n",
            "Two checkpoint references resolved to different objects (<tensorflow.python.keras.layers.convolutional.Conv2DTranspose object at 0x7facd6077b38> and <tensorflow.python.keras.layers.normalization.LayerNormalization object at 0x7facd6077e80>).\n",
            "WARNING:tensorflow:Inconsistent references when loading the checkpoint into this object graph. Either the Trackable object references in the Python program have changed in an incompatible way, or the checkpoint was generated in an incompatible program.\n",
            "\n",
            "Two checkpoint references resolved to different objects (<tensorflow.python.keras.layers.normalization.LayerNormalization object at 0x7facd6077e80> and <tensorflow.python.keras.layers.convolutional.Conv2DTranspose object at 0x7faccafc51d0>).\n",
            "WARNING:tensorflow:Inconsistent references when loading the checkpoint into this object graph. Either the Trackable object references in the Python program have changed in an incompatible way, or the checkpoint was generated in an incompatible program.\n",
            "\n",
            "Two checkpoint references resolved to different objects (<tensorflow.python.keras.layers.convolutional.Conv2DTranspose object at 0x7faccafc51d0> and <tensorflow.python.keras.layers.normalization.LayerNormalization object at 0x7faccafc5518>).\n",
            "WARNING:tensorflow:Inconsistent references when loading the checkpoint into this object graph. Either the Trackable object references in the Python program have changed in an incompatible way, or the checkpoint was generated in an incompatible program.\n",
            "\n",
            "Two checkpoint references resolved to different objects (<tensorflow.python.keras.layers.normalization.LayerNormalization object at 0x7faccafc5518> and <tensorflow.python.keras.layers.convolutional.UpSampling2D object at 0x7faccafc56a0>).\n",
            "WARNING:tensorflow:Inconsistent references when loading the checkpoint into this object graph. Either the Trackable object references in the Python program have changed in an incompatible way, or the checkpoint was generated in an incompatible program.\n",
            "\n",
            "Two checkpoint references resolved to different objects (<tensorflow.python.keras.layers.convolutional.Conv2DTranspose object at 0x7faccafc5978> and <tensorflow.python.keras.layers.normalization.LayerNormalization object at 0x7faccafc5cc0>).\n",
            "WARNING:tensorflow:Inconsistent references when loading the checkpoint into this object graph. Either the Trackable object references in the Python program have changed in an incompatible way, or the checkpoint was generated in an incompatible program.\n",
            "\n",
            "Two checkpoint references resolved to different objects (<tensorflow.python.keras.layers.normalization.LayerNormalization object at 0x7faccafc5cc0> and <tensorflow.python.keras.layers.convolutional.Conv2DTranspose object at 0x7faccafc5fd0>).\n",
            "WARNING:tensorflow:Inconsistent references when loading the checkpoint into this object graph. Either the Trackable object references in the Python program have changed in an incompatible way, or the checkpoint was generated in an incompatible program.\n",
            "\n",
            "Two checkpoint references resolved to different objects (<tensorflow.python.keras.layers.convolutional.Conv2DTranspose object at 0x7faccafc5fd0> and <tensorflow.python.keras.layers.normalization.LayerNormalization object at 0x7faccafce358>).\n",
            "WARNING:tensorflow:Inconsistent references when loading the checkpoint into this object graph. Either the Trackable object references in the Python program have changed in an incompatible way, or the checkpoint was generated in an incompatible program.\n",
            "\n",
            "Two checkpoint references resolved to different objects (<tensorflow.python.keras.layers.normalization.LayerNormalization object at 0x7faccafce358> and <tensorflow.python.keras.layers.convolutional.UpSampling2D object at 0x7faccafce4e0>).\n",
            "WARNING:tensorflow:Inconsistent references when loading the checkpoint into this object graph. Either the Trackable object references in the Python program have changed in an incompatible way, or the checkpoint was generated in an incompatible program.\n",
            "\n",
            "Two checkpoint references resolved to different objects (<tensorflow.python.keras.layers.convolutional.Conv2DTranspose object at 0x7faccafce7b8> and <tensorflow.python.keras.layers.normalization.LayerNormalization object at 0x7faccafceb00>).\n",
            "WARNING:tensorflow:Inconsistent references when loading the checkpoint into this object graph. Either the Trackable object references in the Python program have changed in an incompatible way, or the checkpoint was generated in an incompatible program.\n",
            "\n",
            "Two checkpoint references resolved to different objects (<tensorflow.python.keras.layers.normalization.LayerNormalization object at 0x7faccafceb00> and <tensorflow.python.keras.layers.convolutional.Conv2DTranspose object at 0x7faccafcee10>).\n",
            "WARNING:tensorflow:Inconsistent references when loading the checkpoint into this object graph. Either the Trackable object references in the Python program have changed in an incompatible way, or the checkpoint was generated in an incompatible program.\n",
            "\n",
            "Two checkpoint references resolved to different objects (<tensorflow.python.keras.layers.convolutional.Conv2DTranspose object at 0x7faccafcee10> and <tensorflow.python.keras.layers.normalization.LayerNormalization object at 0x7faccafd9198>).\n",
            "WARNING:tensorflow:Inconsistent references when loading the checkpoint into this object graph. Either the Trackable object references in the Python program have changed in an incompatible way, or the checkpoint was generated in an incompatible program.\n",
            "\n",
            "Two checkpoint references resolved to different objects (<tensorflow.python.keras.layers.normalization.LayerNormalization object at 0x7faccafd9198> and <tensorflow.python.keras.layers.convolutional.UpSampling2D object at 0x7faccafd9320>).\n",
            "WARNING:tensorflow:Inconsistent references when loading the checkpoint into this object graph. Either the Trackable object references in the Python program have changed in an incompatible way, or the checkpoint was generated in an incompatible program.\n",
            "\n",
            "Two checkpoint references resolved to different objects (<tensorflow.python.keras.layers.convolutional.Conv2DTranspose object at 0x7faccafd95f8> and <tensorflow.python.keras.layers.normalization.LayerNormalization object at 0x7faccafd9940>).\n",
            "WARNING:tensorflow:Inconsistent references when loading the checkpoint into this object graph. Either the Trackable object references in the Python program have changed in an incompatible way, or the checkpoint was generated in an incompatible program.\n",
            "\n",
            "Two checkpoint references resolved to different objects (<tensorflow.python.keras.layers.normalization.LayerNormalization object at 0x7faccafd9940> and <tensorflow.python.keras.layers.convolutional.Conv2DTranspose object at 0x7faccafd9c50>).\n",
            "WARNING:tensorflow:Inconsistent references when loading the checkpoint into this object graph. Either the Trackable object references in the Python program have changed in an incompatible way, or the checkpoint was generated in an incompatible program.\n",
            "\n",
            "Two checkpoint references resolved to different objects (<tensorflow.python.keras.layers.convolutional.Conv2DTranspose object at 0x7faccafd9c50> and <tensorflow.python.keras.layers.normalization.LayerNormalization object at 0x7faccafd9f98>).\n",
            "WARNING:tensorflow:Inconsistent references when loading the checkpoint into this object graph. Either the Trackable object references in the Python program have changed in an incompatible way, or the checkpoint was generated in an incompatible program.\n",
            "\n",
            "Two checkpoint references resolved to different objects (<tensorflow.python.keras.layers.normalization.LayerNormalization object at 0x7faccafd9f98> and <tensorflow.python.keras.layers.convolutional.UpSampling2D object at 0x7faccafe4160>).\n",
            "WARNING:tensorflow:Inconsistent references when loading the checkpoint into this object graph. Either the Trackable object references in the Python program have changed in an incompatible way, or the checkpoint was generated in an incompatible program.\n",
            "\n",
            "Two checkpoint references resolved to different objects (<tensorflow.python.keras.layers.convolutional.Conv2DTranspose object at 0x7faccafe4438> and <tensorflow.python.keras.layers.normalization.LayerNormalization object at 0x7faccafe4780>).\n",
            "WARNING:tensorflow:Inconsistent references when loading the checkpoint into this object graph. Either the Trackable object references in the Python program have changed in an incompatible way, or the checkpoint was generated in an incompatible program.\n",
            "\n",
            "Two checkpoint references resolved to different objects (<tensorflow.python.keras.layers.normalization.LayerNormalization object at 0x7faccafe4780> and <tensorflow.python.keras.layers.convolutional.Conv2DTranspose object at 0x7faccafe4a90>).\n",
            "WARNING:tensorflow:Inconsistent references when loading the checkpoint into this object graph. Either the Trackable object references in the Python program have changed in an incompatible way, or the checkpoint was generated in an incompatible program.\n",
            "\n",
            "Two checkpoint references resolved to different objects (<tensorflow.python.keras.layers.convolutional.Conv2DTranspose object at 0x7faccafe4a90> and <tensorflow.python.keras.layers.normalization.LayerNormalization object at 0x7faccafe4dd8>).\n",
            "WARNING:tensorflow:Inconsistent references when loading the checkpoint into this object graph. Either the Trackable object references in the Python program have changed in an incompatible way, or the checkpoint was generated in an incompatible program.\n",
            "\n",
            "Two checkpoint references resolved to different objects (<tensorflow.python.keras.layers.normalization.LayerNormalization object at 0x7faccafe4dd8> and <tensorflow.python.keras.layers.convolutional.Conv2DTranspose object at 0x7faccafe4fd0>).\n",
            "Success Loading Trained Model!\n",
            "\n",
            "2020-05-15 08:23:50.083759: I tensorflow/stream_executor/platform/default/dso_loader.cc:44] Successfully opened dynamic library libcublas.so.10\n",
            "2020-05-15 08:23:51.597366: I tensorflow/stream_executor/platform/default/dso_loader.cc:44] Successfully opened dynamic library libcudnn.so.7\n",
            "2020-05-15 08:23:56.789819: I tensorflow/stream_executor/platform/default/dso_loader.cc:44] Successfully opened dynamic library libcufft.so.10\n",
            "Chord 1 generated!\n",
            "Chord 2 generated!\n",
            "Chord 3 generated!\n",
            "Chord 4 generated!\n",
            "Chord 5 generated!\n",
            "Chord 6 generated!\n",
            "\n",
            "\n",
            "SUCCESS: ALL CHORDS GENERATED!    (chords are saved at ./generated_chords/)\n"
          ],
          "name": "stdout"
        }
      ]
    },
    {
      "cell_type": "code",
      "metadata": {
        "id": "52O-A6_wbZcB",
        "colab_type": "code",
        "outputId": "18deda24-f139-4924-916b-68e74afe9ce4",
        "colab": {
          "base_uri": "https://localhost:8080/",
          "height": 1000
        }
      },
      "source": [
        "!python timbrenet_generate_latent_map.py"
      ],
      "execution_count": 0,
      "outputs": [
        {
          "output_type": "stream",
          "text": [
            "2020-05-15 08:39:42.086931: I tensorflow/stream_executor/platform/default/dso_loader.cc:44] Successfully opened dynamic library libcudart.so.10.1\n",
            "2020-05-15 08:39:44.350220: I tensorflow/stream_executor/platform/default/dso_loader.cc:44] Successfully opened dynamic library libcuda.so.1\n",
            "2020-05-15 08:39:44.376785: I tensorflow/stream_executor/cuda/cuda_gpu_executor.cc:981] successful NUMA node read from SysFS had negative value (-1), but there must be at least one NUMA node, so returning NUMA node zero\n",
            "2020-05-15 08:39:44.377453: I tensorflow/core/common_runtime/gpu/gpu_device.cc:1561] Found device 0 with properties: \n",
            "pciBusID: 0000:00:04.0 name: Tesla P4 computeCapability: 6.1\n",
            "coreClock: 1.1135GHz coreCount: 20 deviceMemorySize: 7.43GiB deviceMemoryBandwidth: 178.99GiB/s\n",
            "2020-05-15 08:39:44.377491: I tensorflow/stream_executor/platform/default/dso_loader.cc:44] Successfully opened dynamic library libcudart.so.10.1\n",
            "2020-05-15 08:39:44.379241: I tensorflow/stream_executor/platform/default/dso_loader.cc:44] Successfully opened dynamic library libcublas.so.10\n",
            "2020-05-15 08:39:44.381114: I tensorflow/stream_executor/platform/default/dso_loader.cc:44] Successfully opened dynamic library libcufft.so.10\n",
            "2020-05-15 08:39:44.381447: I tensorflow/stream_executor/platform/default/dso_loader.cc:44] Successfully opened dynamic library libcurand.so.10\n",
            "2020-05-15 08:39:44.383176: I tensorflow/stream_executor/platform/default/dso_loader.cc:44] Successfully opened dynamic library libcusolver.so.10\n",
            "2020-05-15 08:39:44.387177: I tensorflow/stream_executor/platform/default/dso_loader.cc:44] Successfully opened dynamic library libcusparse.so.10\n",
            "2020-05-15 08:39:44.391155: I tensorflow/stream_executor/platform/default/dso_loader.cc:44] Successfully opened dynamic library libcudnn.so.7\n",
            "2020-05-15 08:39:44.391280: I tensorflow/stream_executor/cuda/cuda_gpu_executor.cc:981] successful NUMA node read from SysFS had negative value (-1), but there must be at least one NUMA node, so returning NUMA node zero\n",
            "2020-05-15 08:39:44.391976: I tensorflow/stream_executor/cuda/cuda_gpu_executor.cc:981] successful NUMA node read from SysFS had negative value (-1), but there must be at least one NUMA node, so returning NUMA node zero\n",
            "2020-05-15 08:39:44.392546: I tensorflow/core/common_runtime/gpu/gpu_device.cc:1703] Adding visible gpu devices: 0\n",
            "2020-05-15 08:39:44.392913: I tensorflow/core/platform/cpu_feature_guard.cc:143] Your CPU supports instructions that this TensorFlow binary was not compiled to use: AVX512F\n",
            "2020-05-15 08:39:44.398172: I tensorflow/core/platform/profile_utils/cpu_utils.cc:102] CPU Frequency: 2000160000 Hz\n",
            "2020-05-15 08:39:44.398380: I tensorflow/compiler/xla/service/service.cc:168] XLA service 0x2959100 initialized for platform Host (this does not guarantee that XLA will be used). Devices:\n",
            "2020-05-15 08:39:44.398410: I tensorflow/compiler/xla/service/service.cc:176]   StreamExecutor device (0): Host, Default Version\n",
            "2020-05-15 08:39:44.494846: I tensorflow/stream_executor/cuda/cuda_gpu_executor.cc:981] successful NUMA node read from SysFS had negative value (-1), but there must be at least one NUMA node, so returning NUMA node zero\n",
            "2020-05-15 08:39:44.495416: I tensorflow/compiler/xla/service/service.cc:168] XLA service 0x29592c0 initialized for platform CUDA (this does not guarantee that XLA will be used). Devices:\n",
            "2020-05-15 08:39:44.495448: I tensorflow/compiler/xla/service/service.cc:176]   StreamExecutor device (0): Tesla P4, Compute Capability 6.1\n",
            "2020-05-15 08:39:44.495649: I tensorflow/stream_executor/cuda/cuda_gpu_executor.cc:981] successful NUMA node read from SysFS had negative value (-1), but there must be at least one NUMA node, so returning NUMA node zero\n",
            "2020-05-15 08:39:44.496043: I tensorflow/core/common_runtime/gpu/gpu_device.cc:1561] Found device 0 with properties: \n",
            "pciBusID: 0000:00:04.0 name: Tesla P4 computeCapability: 6.1\n",
            "coreClock: 1.1135GHz coreCount: 20 deviceMemorySize: 7.43GiB deviceMemoryBandwidth: 178.99GiB/s\n",
            "2020-05-15 08:39:44.496091: I tensorflow/stream_executor/platform/default/dso_loader.cc:44] Successfully opened dynamic library libcudart.so.10.1\n",
            "2020-05-15 08:39:44.496154: I tensorflow/stream_executor/platform/default/dso_loader.cc:44] Successfully opened dynamic library libcublas.so.10\n",
            "2020-05-15 08:39:44.496183: I tensorflow/stream_executor/platform/default/dso_loader.cc:44] Successfully opened dynamic library libcufft.so.10\n",
            "2020-05-15 08:39:44.496209: I tensorflow/stream_executor/platform/default/dso_loader.cc:44] Successfully opened dynamic library libcurand.so.10\n",
            "2020-05-15 08:39:44.496230: I tensorflow/stream_executor/platform/default/dso_loader.cc:44] Successfully opened dynamic library libcusolver.so.10\n",
            "2020-05-15 08:39:44.496252: I tensorflow/stream_executor/platform/default/dso_loader.cc:44] Successfully opened dynamic library libcusparse.so.10\n",
            "2020-05-15 08:39:44.496276: I tensorflow/stream_executor/platform/default/dso_loader.cc:44] Successfully opened dynamic library libcudnn.so.7\n",
            "2020-05-15 08:39:44.496359: I tensorflow/stream_executor/cuda/cuda_gpu_executor.cc:981] successful NUMA node read from SysFS had negative value (-1), but there must be at least one NUMA node, so returning NUMA node zero\n",
            "2020-05-15 08:39:44.496762: I tensorflow/stream_executor/cuda/cuda_gpu_executor.cc:981] successful NUMA node read from SysFS had negative value (-1), but there must be at least one NUMA node, so returning NUMA node zero\n",
            "2020-05-15 08:39:44.497161: I tensorflow/core/common_runtime/gpu/gpu_device.cc:1703] Adding visible gpu devices: 0\n",
            "2020-05-15 08:39:44.497223: I tensorflow/stream_executor/platform/default/dso_loader.cc:44] Successfully opened dynamic library libcudart.so.10.1\n",
            "2020-05-15 08:39:45.038027: I tensorflow/core/common_runtime/gpu/gpu_device.cc:1102] Device interconnect StreamExecutor with strength 1 edge matrix:\n",
            "2020-05-15 08:39:45.038085: I tensorflow/core/common_runtime/gpu/gpu_device.cc:1108]      0 \n",
            "2020-05-15 08:39:45.038099: I tensorflow/core/common_runtime/gpu/gpu_device.cc:1121] 0:   N \n",
            "2020-05-15 08:39:45.038329: I tensorflow/stream_executor/cuda/cuda_gpu_executor.cc:981] successful NUMA node read from SysFS had negative value (-1), but there must be at least one NUMA node, so returning NUMA node zero\n",
            "2020-05-15 08:39:45.038790: I tensorflow/stream_executor/cuda/cuda_gpu_executor.cc:981] successful NUMA node read from SysFS had negative value (-1), but there must be at least one NUMA node, so returning NUMA node zero\n",
            "2020-05-15 08:39:45.039192: W tensorflow/core/common_runtime/gpu/gpu_bfc_allocator.cc:39] Overriding allow_growth setting because the TF_FORCE_GPU_ALLOW_GROWTH environment variable is set. Original config value was 0.\n",
            "2020-05-15 08:39:45.039242: I tensorflow/core/common_runtime/gpu/gpu_device.cc:1247] Created TensorFlow device (/job:localhost/replica:0/task:0/device:GPU:0 with 6966 MB memory) -> physical GPU (device: 0, name: Tesla P4, pci bus id: 0000:00:04.0, compute capability: 6.1)\n",
            "\n",
            "\n",
            "Loading Trained Model...\n",
            "WARNING:tensorflow:Inconsistent references when loading the checkpoint into this object graph. Either the Trackable object references in the Python program have changed in an incompatible way, or the checkpoint was generated in an incompatible program.\n",
            "\n",
            "Two checkpoint references resolved to different objects (<tensorflow.python.keras.layers.convolutional.Conv2D object at 0x7fbf076b05f8> and <tensorflow.python.keras.layers.convolutional.Conv2D object at 0x7fbeede84550>).\n",
            "WARNING:tensorflow:Inconsistent references when loading the checkpoint into this object graph. Either the Trackable object references in the Python program have changed in an incompatible way, or the checkpoint was generated in an incompatible program.\n",
            "\n",
            "Two checkpoint references resolved to different objects (<tensorflow.python.keras.layers.convolutional.Conv2D object at 0x7fbeede84550> and <tensorflow.python.keras.layers.convolutional.Conv2D object at 0x7fbeede849e8>).\n",
            "WARNING:tensorflow:Inconsistent references when loading the checkpoint into this object graph. Either the Trackable object references in the Python program have changed in an incompatible way, or the checkpoint was generated in an incompatible program.\n",
            "\n",
            "Two checkpoint references resolved to different objects (<tensorflow.python.keras.layers.convolutional.Conv2D object at 0x7fbeede849e8> and <tensorflow.python.keras.layers.pooling.AveragePooling2D object at 0x7fbeede84d68>).\n",
            "WARNING:tensorflow:Inconsistent references when loading the checkpoint into this object graph. Either the Trackable object references in the Python program have changed in an incompatible way, or the checkpoint was generated in an incompatible program.\n",
            "\n",
            "Two checkpoint references resolved to different objects (<tensorflow.python.keras.layers.convolutional.Conv2D object at 0x7fbeedeaa080> and <tensorflow.python.keras.layers.convolutional.Conv2D object at 0x7fbeedeaa518>).\n",
            "WARNING:tensorflow:Inconsistent references when loading the checkpoint into this object graph. Either the Trackable object references in the Python program have changed in an incompatible way, or the checkpoint was generated in an incompatible program.\n",
            "\n",
            "Two checkpoint references resolved to different objects (<tensorflow.python.keras.layers.convolutional.Conv2D object at 0x7fbeedeaa518> and <tensorflow.python.keras.layers.pooling.AveragePooling2D object at 0x7fbeedeaa898>).\n",
            "WARNING:tensorflow:Inconsistent references when loading the checkpoint into this object graph. Either the Trackable object references in the Python program have changed in an incompatible way, or the checkpoint was generated in an incompatible program.\n",
            "\n",
            "Two checkpoint references resolved to different objects (<tensorflow.python.keras.layers.convolutional.Conv2D object at 0x7fbeedeaab70> and <tensorflow.python.keras.layers.convolutional.Conv2D object at 0x7fbeedeb3048>).\n",
            "WARNING:tensorflow:Inconsistent references when loading the checkpoint into this object graph. Either the Trackable object references in the Python program have changed in an incompatible way, or the checkpoint was generated in an incompatible program.\n",
            "\n",
            "Two checkpoint references resolved to different objects (<tensorflow.python.keras.layers.convolutional.Conv2D object at 0x7fbeedeb3048> and <tensorflow.python.keras.layers.pooling.AveragePooling2D object at 0x7fbeedeb33c8>).\n",
            "WARNING:tensorflow:Inconsistent references when loading the checkpoint into this object graph. Either the Trackable object references in the Python program have changed in an incompatible way, or the checkpoint was generated in an incompatible program.\n",
            "\n",
            "Two checkpoint references resolved to different objects (<tensorflow.python.keras.layers.convolutional.Conv2D object at 0x7fbeedeb36a0> and <tensorflow.python.keras.layers.convolutional.Conv2D object at 0x7fbeedeb3b38>).\n",
            "WARNING:tensorflow:Inconsistent references when loading the checkpoint into this object graph. Either the Trackable object references in the Python program have changed in an incompatible way, or the checkpoint was generated in an incompatible program.\n",
            "\n",
            "Two checkpoint references resolved to different objects (<tensorflow.python.keras.layers.convolutional.Conv2D object at 0x7fbeedeb3b38> and <tensorflow.python.keras.layers.pooling.AveragePooling2D object at 0x7fbeedeb3eb8>).\n",
            "WARNING:tensorflow:Inconsistent references when loading the checkpoint into this object graph. Either the Trackable object references in the Python program have changed in an incompatible way, or the checkpoint was generated in an incompatible program.\n",
            "\n",
            "Two checkpoint references resolved to different objects (<tensorflow.python.keras.layers.convolutional.Conv2D object at 0x7fbeede3e1d0> and <tensorflow.python.keras.layers.convolutional.Conv2D object at 0x7fbeede3e668>).\n",
            "WARNING:tensorflow:Inconsistent references when loading the checkpoint into this object graph. Either the Trackable object references in the Python program have changed in an incompatible way, or the checkpoint was generated in an incompatible program.\n",
            "\n",
            "Two checkpoint references resolved to different objects (<tensorflow.python.keras.layers.convolutional.Conv2D object at 0x7fbeede3e668> and <tensorflow.python.keras.layers.pooling.AveragePooling2D object at 0x7fbeede3e9e8>).\n",
            "WARNING:tensorflow:Inconsistent references when loading the checkpoint into this object graph. Either the Trackable object references in the Python program have changed in an incompatible way, or the checkpoint was generated in an incompatible program.\n",
            "\n",
            "Two checkpoint references resolved to different objects (<tensorflow.python.keras.layers.convolutional.Conv2D object at 0x7fbeede3ecc0> and <tensorflow.python.keras.layers.convolutional.Conv2D object at 0x7fbeede48198>).\n",
            "WARNING:tensorflow:Inconsistent references when loading the checkpoint into this object graph. Either the Trackable object references in the Python program have changed in an incompatible way, or the checkpoint was generated in an incompatible program.\n",
            "\n",
            "Two checkpoint references resolved to different objects (<tensorflow.python.keras.layers.convolutional.Conv2D object at 0x7fbeede48198> and <tensorflow.python.keras.layers.pooling.AveragePooling2D object at 0x7fbeede48518>).\n",
            "WARNING:tensorflow:Inconsistent references when loading the checkpoint into this object graph. Either the Trackable object references in the Python program have changed in an incompatible way, or the checkpoint was generated in an incompatible program.\n",
            "\n",
            "Two checkpoint references resolved to different objects (<tensorflow.python.keras.layers.convolutional.Conv2D object at 0x7fbeede487f0> and <tensorflow.python.keras.layers.convolutional.Conv2D object at 0x7fbeede48c88>).\n",
            "WARNING:tensorflow:Inconsistent references when loading the checkpoint into this object graph. Either the Trackable object references in the Python program have changed in an incompatible way, or the checkpoint was generated in an incompatible program.\n",
            "\n",
            "Two checkpoint references resolved to different objects (<tensorflow.python.keras.layers.convolutional.Conv2D object at 0x7fbeede48c88> and <tensorflow.python.keras.layers.pooling.AveragePooling2D object at 0x7fbeede53048>).\n",
            "WARNING:tensorflow:Inconsistent references when loading the checkpoint into this object graph. Either the Trackable object references in the Python program have changed in an incompatible way, or the checkpoint was generated in an incompatible program.\n",
            "\n",
            "Two checkpoint references resolved to different objects (<tensorflow.python.keras.layers.core.Dense object at 0x7fbee03ed6a0> and <tensorflow.python.keras.layers.core.Reshape object at 0x7fbee03763c8>).\n",
            "WARNING:tensorflow:Inconsistent references when loading the checkpoint into this object graph. Either the Trackable object references in the Python program have changed in an incompatible way, or the checkpoint was generated in an incompatible program.\n",
            "\n",
            "Two checkpoint references resolved to different objects (<tensorflow.python.keras.layers.convolutional.Conv2DTranspose object at 0x7fbee0376978> and <tensorflow.python.keras.layers.normalization.LayerNormalization object at 0x7fbee0376cc0>).\n",
            "WARNING:tensorflow:Inconsistent references when loading the checkpoint into this object graph. Either the Trackable object references in the Python program have changed in an incompatible way, or the checkpoint was generated in an incompatible program.\n",
            "\n",
            "Two checkpoint references resolved to different objects (<tensorflow.python.keras.layers.normalization.LayerNormalization object at 0x7fbee0376cc0> and <tensorflow.python.keras.layers.convolutional.Conv2DTranspose object at 0x7fbee0376fd0>).\n",
            "WARNING:tensorflow:Inconsistent references when loading the checkpoint into this object graph. Either the Trackable object references in the Python program have changed in an incompatible way, or the checkpoint was generated in an incompatible program.\n",
            "\n",
            "Two checkpoint references resolved to different objects (<tensorflow.python.keras.layers.convolutional.Conv2DTranspose object at 0x7fbee0376fd0> and <tensorflow.python.keras.layers.normalization.LayerNormalization object at 0x7fbeede9a358>).\n",
            "WARNING:tensorflow:Inconsistent references when loading the checkpoint into this object graph. Either the Trackable object references in the Python program have changed in an incompatible way, or the checkpoint was generated in an incompatible program.\n",
            "\n",
            "Two checkpoint references resolved to different objects (<tensorflow.python.keras.layers.normalization.LayerNormalization object at 0x7fbeede9a358> and <tensorflow.python.keras.layers.convolutional.UpSampling2D object at 0x7fbeede9a4e0>).\n",
            "WARNING:tensorflow:Inconsistent references when loading the checkpoint into this object graph. Either the Trackable object references in the Python program have changed in an incompatible way, or the checkpoint was generated in an incompatible program.\n",
            "\n",
            "Two checkpoint references resolved to different objects (<tensorflow.python.keras.layers.convolutional.Conv2DTranspose object at 0x7fbeede9a7b8> and <tensorflow.python.keras.layers.normalization.LayerNormalization object at 0x7fbeede9ab00>).\n",
            "WARNING:tensorflow:Inconsistent references when loading the checkpoint into this object graph. Either the Trackable object references in the Python program have changed in an incompatible way, or the checkpoint was generated in an incompatible program.\n",
            "\n",
            "Two checkpoint references resolved to different objects (<tensorflow.python.keras.layers.normalization.LayerNormalization object at 0x7fbeede9ab00> and <tensorflow.python.keras.layers.convolutional.Conv2DTranspose object at 0x7fbeede9ae10>).\n",
            "WARNING:tensorflow:Inconsistent references when loading the checkpoint into this object graph. Either the Trackable object references in the Python program have changed in an incompatible way, or the checkpoint was generated in an incompatible program.\n",
            "\n",
            "Two checkpoint references resolved to different objects (<tensorflow.python.keras.layers.convolutional.Conv2DTranspose object at 0x7fbeede9ae10> and <tensorflow.python.keras.layers.normalization.LayerNormalization object at 0x7fbee0385198>).\n",
            "WARNING:tensorflow:Inconsistent references when loading the checkpoint into this object graph. Either the Trackable object references in the Python program have changed in an incompatible way, or the checkpoint was generated in an incompatible program.\n",
            "\n",
            "Two checkpoint references resolved to different objects (<tensorflow.python.keras.layers.normalization.LayerNormalization object at 0x7fbee0385198> and <tensorflow.python.keras.layers.convolutional.UpSampling2D object at 0x7fbee0385320>).\n",
            "WARNING:tensorflow:Inconsistent references when loading the checkpoint into this object graph. Either the Trackable object references in the Python program have changed in an incompatible way, or the checkpoint was generated in an incompatible program.\n",
            "\n",
            "Two checkpoint references resolved to different objects (<tensorflow.python.keras.layers.convolutional.Conv2DTranspose object at 0x7fbee03855f8> and <tensorflow.python.keras.layers.normalization.LayerNormalization object at 0x7fbee0385940>).\n",
            "WARNING:tensorflow:Inconsistent references when loading the checkpoint into this object graph. Either the Trackable object references in the Python program have changed in an incompatible way, or the checkpoint was generated in an incompatible program.\n",
            "\n",
            "Two checkpoint references resolved to different objects (<tensorflow.python.keras.layers.normalization.LayerNormalization object at 0x7fbee0385940> and <tensorflow.python.keras.layers.convolutional.Conv2DTranspose object at 0x7fbee0385c50>).\n",
            "WARNING:tensorflow:Inconsistent references when loading the checkpoint into this object graph. Either the Trackable object references in the Python program have changed in an incompatible way, or the checkpoint was generated in an incompatible program.\n",
            "\n",
            "Two checkpoint references resolved to different objects (<tensorflow.python.keras.layers.convolutional.Conv2DTranspose object at 0x7fbee0385c50> and <tensorflow.python.keras.layers.normalization.LayerNormalization object at 0x7fbee0385f98>).\n",
            "WARNING:tensorflow:Inconsistent references when loading the checkpoint into this object graph. Either the Trackable object references in the Python program have changed in an incompatible way, or the checkpoint was generated in an incompatible program.\n",
            "\n",
            "Two checkpoint references resolved to different objects (<tensorflow.python.keras.layers.normalization.LayerNormalization object at 0x7fbee0385f98> and <tensorflow.python.keras.layers.convolutional.UpSampling2D object at 0x7fbee038e160>).\n",
            "WARNING:tensorflow:Inconsistent references when loading the checkpoint into this object graph. Either the Trackable object references in the Python program have changed in an incompatible way, or the checkpoint was generated in an incompatible program.\n",
            "\n",
            "Two checkpoint references resolved to different objects (<tensorflow.python.keras.layers.convolutional.Conv2DTranspose object at 0x7fbee038e438> and <tensorflow.python.keras.layers.normalization.LayerNormalization object at 0x7fbee038e780>).\n",
            "WARNING:tensorflow:Inconsistent references when loading the checkpoint into this object graph. Either the Trackable object references in the Python program have changed in an incompatible way, or the checkpoint was generated in an incompatible program.\n",
            "\n",
            "Two checkpoint references resolved to different objects (<tensorflow.python.keras.layers.normalization.LayerNormalization object at 0x7fbee038e780> and <tensorflow.python.keras.layers.convolutional.Conv2DTranspose object at 0x7fbee038ea90>).\n",
            "WARNING:tensorflow:Inconsistent references when loading the checkpoint into this object graph. Either the Trackable object references in the Python program have changed in an incompatible way, or the checkpoint was generated in an incompatible program.\n",
            "\n",
            "Two checkpoint references resolved to different objects (<tensorflow.python.keras.layers.convolutional.Conv2DTranspose object at 0x7fbee038ea90> and <tensorflow.python.keras.layers.normalization.LayerNormalization object at 0x7fbee038edd8>).\n",
            "WARNING:tensorflow:Inconsistent references when loading the checkpoint into this object graph. Either the Trackable object references in the Python program have changed in an incompatible way, or the checkpoint was generated in an incompatible program.\n",
            "\n",
            "Two checkpoint references resolved to different objects (<tensorflow.python.keras.layers.normalization.LayerNormalization object at 0x7fbee038edd8> and <tensorflow.python.keras.layers.convolutional.UpSampling2D object at 0x7fbee038ef60>).\n",
            "WARNING:tensorflow:Inconsistent references when loading the checkpoint into this object graph. Either the Trackable object references in the Python program have changed in an incompatible way, or the checkpoint was generated in an incompatible program.\n",
            "\n",
            "Two checkpoint references resolved to different objects (<tensorflow.python.keras.layers.convolutional.Conv2DTranspose object at 0x7fbee0399278> and <tensorflow.python.keras.layers.normalization.LayerNormalization object at 0x7fbee03995c0>).\n",
            "WARNING:tensorflow:Inconsistent references when loading the checkpoint into this object graph. Either the Trackable object references in the Python program have changed in an incompatible way, or the checkpoint was generated in an incompatible program.\n",
            "\n",
            "Two checkpoint references resolved to different objects (<tensorflow.python.keras.layers.normalization.LayerNormalization object at 0x7fbee03995c0> and <tensorflow.python.keras.layers.convolutional.Conv2DTranspose object at 0x7fbee03998d0>).\n",
            "WARNING:tensorflow:Inconsistent references when loading the checkpoint into this object graph. Either the Trackable object references in the Python program have changed in an incompatible way, or the checkpoint was generated in an incompatible program.\n",
            "\n",
            "Two checkpoint references resolved to different objects (<tensorflow.python.keras.layers.convolutional.Conv2DTranspose object at 0x7fbee03998d0> and <tensorflow.python.keras.layers.normalization.LayerNormalization object at 0x7fbee0399c18>).\n",
            "WARNING:tensorflow:Inconsistent references when loading the checkpoint into this object graph. Either the Trackable object references in the Python program have changed in an incompatible way, or the checkpoint was generated in an incompatible program.\n",
            "\n",
            "Two checkpoint references resolved to different objects (<tensorflow.python.keras.layers.normalization.LayerNormalization object at 0x7fbee0399c18> and <tensorflow.python.keras.layers.convolutional.UpSampling2D object at 0x7fbee0399da0>).\n",
            "WARNING:tensorflow:Inconsistent references when loading the checkpoint into this object graph. Either the Trackable object references in the Python program have changed in an incompatible way, or the checkpoint was generated in an incompatible program.\n",
            "\n",
            "Two checkpoint references resolved to different objects (<tensorflow.python.keras.layers.convolutional.Conv2DTranspose object at 0x7fbee03a10b8> and <tensorflow.python.keras.layers.normalization.LayerNormalization object at 0x7fbee03a1400>).\n",
            "WARNING:tensorflow:Inconsistent references when loading the checkpoint into this object graph. Either the Trackable object references in the Python program have changed in an incompatible way, or the checkpoint was generated in an incompatible program.\n",
            "\n",
            "Two checkpoint references resolved to different objects (<tensorflow.python.keras.layers.normalization.LayerNormalization object at 0x7fbee03a1400> and <tensorflow.python.keras.layers.convolutional.Conv2DTranspose object at 0x7fbee03a1710>).\n",
            "WARNING:tensorflow:Inconsistent references when loading the checkpoint into this object graph. Either the Trackable object references in the Python program have changed in an incompatible way, or the checkpoint was generated in an incompatible program.\n",
            "\n",
            "Two checkpoint references resolved to different objects (<tensorflow.python.keras.layers.convolutional.Conv2DTranspose object at 0x7fbee03a1710> and <tensorflow.python.keras.layers.normalization.LayerNormalization object at 0x7fbee03a1a58>).\n",
            "WARNING:tensorflow:Inconsistent references when loading the checkpoint into this object graph. Either the Trackable object references in the Python program have changed in an incompatible way, or the checkpoint was generated in an incompatible program.\n",
            "\n",
            "Two checkpoint references resolved to different objects (<tensorflow.python.keras.layers.normalization.LayerNormalization object at 0x7fbee03a1a58> and <tensorflow.python.keras.layers.convolutional.UpSampling2D object at 0x7fbee03a1be0>).\n",
            "WARNING:tensorflow:Inconsistent references when loading the checkpoint into this object graph. Either the Trackable object references in the Python program have changed in an incompatible way, or the checkpoint was generated in an incompatible program.\n",
            "\n",
            "Two checkpoint references resolved to different objects (<tensorflow.python.keras.layers.convolutional.Conv2DTranspose object at 0x7fbee03a1eb8> and <tensorflow.python.keras.layers.normalization.LayerNormalization object at 0x7fbee03ac240>).\n",
            "WARNING:tensorflow:Inconsistent references when loading the checkpoint into this object graph. Either the Trackable object references in the Python program have changed in an incompatible way, or the checkpoint was generated in an incompatible program.\n",
            "\n",
            "Two checkpoint references resolved to different objects (<tensorflow.python.keras.layers.normalization.LayerNormalization object at 0x7fbee03ac240> and <tensorflow.python.keras.layers.convolutional.Conv2DTranspose object at 0x7fbee03ac550>).\n",
            "WARNING:tensorflow:Inconsistent references when loading the checkpoint into this object graph. Either the Trackable object references in the Python program have changed in an incompatible way, or the checkpoint was generated in an incompatible program.\n",
            "\n",
            "Two checkpoint references resolved to different objects (<tensorflow.python.keras.layers.convolutional.Conv2DTranspose object at 0x7fbee03ac550> and <tensorflow.python.keras.layers.normalization.LayerNormalization object at 0x7fbee03ac898>).\n",
            "WARNING:tensorflow:Inconsistent references when loading the checkpoint into this object graph. Either the Trackable object references in the Python program have changed in an incompatible way, or the checkpoint was generated in an incompatible program.\n",
            "\n",
            "Two checkpoint references resolved to different objects (<tensorflow.python.keras.layers.normalization.LayerNormalization object at 0x7fbee03ac898> and <tensorflow.python.keras.layers.convolutional.Conv2DTranspose object at 0x7fbee03aca90>).\n",
            "Success Loading Trained Model!\n",
            "\n",
            "\n",
            "\n",
            "Importing Dataset...\n",
            "2020-05-15 08:39:46.107037: I tensorflow/stream_executor/platform/default/dso_loader.cc:44] Successfully opened dynamic library libcufft.so.10\n",
            "2020-05-15 08:39:46.384129: I tensorflow/stream_executor/platform/default/dso_loader.cc:44] Successfully opened dynamic library libcublas.so.10\n",
            "2020-05-15 08:39:46.654964: I tensorflow/stream_executor/platform/default/dso_loader.cc:44] Successfully opened dynamic library libcudnn.so.7\n",
            "Success Importing Dataset!\n",
            "\n",
            "\n",
            "\n",
            "Generating map for latent = 2\n",
            "<Figure size 1300x1300 with 1 Axes>\n"
          ],
          "name": "stdout"
        }
      ]
    },
    {
      "cell_type": "code",
      "metadata": {
        "id": "IsziX3dEeYSZ",
        "colab_type": "code",
        "colab": {}
      },
      "source": [
        ""
      ],
      "execution_count": 0,
      "outputs": []
    }
  ]
}